<?xml version="1.0" encoding="utf-8"?>
<!-- This URDF was automatically created by SolidWorks to URDF Exporter! Originally created by Stephen Brawner (brawner@gmail.com)
     Commit Version: 1.6.0-4-g7f85cfe  Build Version: 1.6.7995.38578
     For more information, please see http://wiki.ros.org/sw_urdf_exporter -->
<robot name="x2">

  <mujoco>
    <compiler meshdir="meshes" discardvisual="false"/>
  </mujoco>

<!--  <link name="world"></link>-->
<!--  <joint name="pelvis_link" type="floating">-->
<!--    <parent link="world"/>-->
<!--    <child link="pelvis_link"/>-->
<!--  </joint>-->

  <link name="pelvis_link">
    <inertial>
      <origin xyz="0 0 0.001" rpy="0 0 0" />
      <mass value="0.1" />
      <inertia ixx="0.00003053" ixy="0.0000000" ixz="0.00000000" iyy="0.00003053" iyz="0.00000000" izz="0.00000500" />
    </inertial>
    <visual>
      <origin xyz="0 0 0" rpy="0 0 0" />
      <geometry>
        <mesh filename="meshes/pelvis_link.STL" />
      </geometry>
      <material name="">
        <color rgba="1 1 1 1" />
      </material>
    </visual>
    <collision>
      <origin xyz="0 0 0.3" rpy="0 0 0" />
      <geometry>
        <box size="0.21 0.25 0.46"/>
      </geometry>
    </collision>
    <!-- <collision>
      <origin xyz="0 0 0" rpy="0 0 0" />
      <geometry>
        <mesh filename="meshes/pelvis_link.STL" />
      </geometry>
    </collision> -->
  </link>
  <link name="L_hip_yaw_link">
    <inertial>
      <origin xyz="-0.0005618 0.01983101 0.00885104" rpy="0 0 0" />
      <mass value="0.841" />
      <inertia ixx="0.00175231" ixy="0.00003788" ixz="0.00000418" iyy="0.00059335" iyz="-0.00014762" izz="0.00173830" />
    </inertial>
    <visual>
      <origin xyz="0 0 0" rpy="0 0 0" />
      <geometry>
        <mesh filename="meshes/L_hip_yaw_link.STL" />
      </geometry>
      <material name="">
        <color rgba="1 1 1 1" />
      </material>
    </visual>
<!--    <collision>-->
<!--      <origin xyz="0 0 0" rpy="0 0 0" />-->
<!--      <geometry>-->
<!--        <mesh filename="meshes/L_hip_yaw_link.STL" />-->
<!--      </geometry>-->
<!--    </collision>-->
  </link>
  <joint name="L_hip_yaw" type="revolute">
    <origin xyz="0 0 0" rpy="0 0 0" />
    <parent link="pelvis_link" />
    <child link="L_hip_yaw_link" />
    <axis xyz="0 0 1" />
    <limit lower="-0.7854" upper="0.7854" effort="83.5" velocity="43" />
  </joint>
  <link name="L_hip_roll_link">
    <inertial>
      <origin xyz="-0.03247252 0.00017925 -0.07264839" rpy="0 0 0" />
      <mass value="2.667" />
      <inertia ixx="0.007970422" ixy="-0.00001767" ixz="0.00171027" iyy="0.01086223" iyz="-0.00001804" izz="0.00754180" />
    </inertial>
    <visual>
      <origin xyz="0 0 0" rpy="0 0 0" />
      <geometry>
        <mesh filename="meshes/L_hip_roll_link.STL" />
      </geometry>
      <material name="">
        <color rgba="1 1 1 1" />
      </material>
    </visual>
    <collision>
      <origin xyz="0 0 0" rpy="0 0 0" />
      <geometry>
        <mesh filename="meshes/L_hip_roll_link.STL" />
      </geometry>
    </collision>
  </link>
  <joint name="L_hip_roll" type="revolute">
    <origin xyz="-0.0095 0.12 0" rpy="0 0 0" />
    <parent link="L_hip_yaw_link" />
    <child link="L_hip_roll_link" />
    <axis xyz="1 0 0" />
    <limit lower="-0.349" upper="0.524" effort="117.8" velocity="90" />
  </joint>
  <link name="L_hip_pitch_link">
    <inertial>
      <origin xyz="0.00382921 0 -0.18548450" rpy="0 0 0" />
      <!-- <mass value="1.664" /> -->
      <mass value="1.8" />
      <inertia ixx="0.01443710" ixy="0.00000000" ixz="-0.00089513" iyy="0.01484426" iyz="-0.00000003" izz="0.00315739" />
    </inertial>
    <visual>
      <origin xyz="0 0 0" rpy="0 0 0" />
      <geometry>
        <mesh filename="meshes/L_hip_pitch_link.STL" />
      </geometry>
      <material name="">
        <color rgba="1 1 1 1" />
      </material>
    </visual>
    <!-- <collision>
      <origin xyz="0 0 0" rpy="0 0 0" />
      <geometry>
        <mesh filename="meshes/L_hip_pitch_link.STL" />
      </geometry>
    </collision> -->
    <collision>
      <origin xyz="0.01 0 -0.175" rpy="0 0 0" />
      <geometry>
        <box size="0.11 0.11 0.23" />
      </geometry>
    </collision>
  </link>
  <joint name="L_hip_pitch" type="revolute">
    <origin xyz="0.0085 -0.001 -0.11" rpy="0 0 0" />
    <parent link="L_hip_roll_link" />
    <child link="L_hip_pitch_link" />
    <axis xyz="0 -1 0" />
    <limit lower="-0.526" upper="2.4434" effort="72" velocity="111" />
  </joint>
  <link name="L_knee_pitch_link">
    <inertial>
      <origin xyz="0.00140265 0 -0.15875986" rpy="0 0 0" />
      <mass value="1.125" />
      <inertia ixx="0.00985892" ixy="0.00000000" ixz="0.00035856" iyy="0.00999859" iyz="-0.00000003" izz="0.00102379" />
    </inertial>
    <visual>
      <origin xyz="0 0 0" rpy="0 0 0" />
      <geometry>
        <mesh filename="meshes/L_knee_pitch_link.STL" />
      </geometry>
      <material name="">
        <color rgba="1 1 1 1" />
      </material>
    </visual>
    <collision>
      <origin xyz="0 0 0" rpy="0 0 0" />
      <geometry>
        <mesh filename="meshes/L_knee_pitch_link.STL" />
      </geometry>
    </collision>
  </link>
  <joint name="L_knee_pitch" type="revolute">
    <origin xyz="0 0 -0.35" rpy="0 0 0" />
    <parent link="L_hip_pitch_link" />
    <child link="L_knee_pitch_link" />
    <axis xyz="0 -1 0" />
    <limit lower="-2.3561" upper="0" effort="64.8" velocity="247" />
  </joint>
  <link name="L_ankle_pitch_link">
    <inertial>
      <origin xyz="-0.00129654 0.00042952 -0.02564546" rpy="0 0 0" />
      <!-- <mass value="0.176" /> -->
      <mass value="0.2" />
      <inertia ixx="0.00018904" ixy="-0.000000108" ixz="0.000000604" iyy="0.00027991" iyz="-0.0000000295" izz="0.00013810" />
    </inertial>
    <visual>
      <origin xyz="0 0 0" rpy="0 0 0" />
      <geometry>
        <mesh filename="meshes/L_ankle_pitch_link.STL" />
      </geometry>
      <material name="">
        <color rgba="1 1 1 1" />
      </material>
    </visual>
<!--    <collision>-->
<!--      <origin xyz="0 0 0" rpy="0 0 0" />-->
<!--      <geometry>-->
<!--        <mesh filename="meshes/L_ankle_pitch_link.STL" />-->
<!--      </geometry>-->
<!--    </collision>-->
  </link>
  <joint name="L_ankle_pitch" type="revolute">
    <origin xyz="0 0 -0.35" rpy="0 0 0" />
    <parent link="L_knee_pitch_link" />
    <child link="L_ankle_pitch_link" />
    <axis xyz="0 -1 0" />
    <limit lower="-1.2217" upper="1.2217" effort="64.8" velocity="247" />
  </joint>
  <link name="L_ankle_roll_link">
    <inertial>
      <origin xyz="0.04923832 -0.00023816 -0.03446415" rpy="0 0 0" />
      <!-- <mass value="0.624" /> -->
      <mass value="1.0" />
      <inertia ixx="0.00038741" ixy="-0.00000505" ixz="-0.00004308" iyy="0.00328461" iyz="0.00000022" izz="0.00357836" />
    </inertial>
    <visual>
      <origin xyz="0 0 0" rpy="0 0 0" />
      <geometry>
        <mesh filename="meshes/L_ankle_roll_link.STL" />
      </geometry>
      <material name="">
        <color rgba="1 1 1 1" />
      </material>
    </visual>
    <collision>
      <origin xyz="0 0 0" rpy="0 0 0" />
      <geometry>
        <mesh filename="meshes/L_ankle_roll_link.STL" />
      </geometry>
    </collision>
  </link>
  <joint name="L_ankle_roll" type="revolute">
    <origin xyz="0 0 -0.045" rpy="0 0 0" />
    <parent link="L_ankle_pitch_link" />
    <child link="L_ankle_roll_link" />
    <axis xyz="1 0 0" />
    <limit lower="-1.047" upper="1.047" effort="20.67" velocity="248" />
  </joint>
  <link name="R_hip_yaw_link">
    <inertial>
      <origin xyz="-0.00116447 -0.04044945 0" rpy="0 0 0" />
      <mass value="0.947" />
      <inertia ixx="0.00258452" ixy="0.00006567" ixz="0.0000000" iyy="0.00068046" iyz="0.00000000" izz="0.00239929" />
    </inertial>
    <visual>
      <origin xyz="0 0 0" rpy="0 0 0" />
      <geometry>
        <mesh filename="meshes/R_hip_yaw_link.STL" />
      </geometry>
      <material name="">
        <color rgba="1 1 1 1" />
      </material>
    </visual>
<!--    <collision>-->
<!--      <origin xyz="0 0 0" rpy="0 0 0" />-->
<!--      <geometry>-->
<!--        <mesh filename="meshes/R_hip_yaw_link.STL" />-->
<!--      </geometry>-->
<!--    </collision>-->
  </link>
  <joint name="R_hip_yaw" type="revolute">
    <origin xyz="0 0 0" rpy="0 0 0" />
    <parent link="pelvis_link" />
    <child link="R_hip_yaw_link" />
    <axis xyz="0 0 -1" />
    <limit lower="-0.7854" upper="0.7854" effort="83.5" velocity="43" />
  </joint>
  <link name="R_hip_roll_link">
    <inertial>
      <origin xyz="-0.03247252 0.00017925 -0.07264839" rpy="0 0 0" />
      <mass value="2.667" />
      <inertia ixx="0.007970422" ixy="-0.00001767" ixz="0.00171027" iyy="0.01086223" iyz="-0.00001804" izz="0.00754180" />
    </inertial>
    <visual>
      <origin xyz="0 0 0" rpy="0 0 0" />
      <geometry>
        <mesh filename="meshes/R_hip_roll_link.STL" />
      </geometry>
      <material name="">
        <color rgba="1 1 1 1" />
      </material>
    </visual>
    <collision>
      <origin xyz="0 0 0" rpy="0 0 0" />
      <geometry>
        <mesh filename="meshes/R_hip_roll_link.STL" />
      </geometry>
    </collision>
  </link>
  <joint name="R_hip_roll" type="revolute">
    <origin xyz="-0.0095 -0.12 0" rpy="0 0 0" />
    <parent link="R_hip_yaw_link" />
    <child link="R_hip_roll_link" />
    <axis xyz="-1 0 0" />
    <limit lower="-0.349" upper="0.524" effort="117.8" velocity="90" />
  </joint>
  <link name="R_hip_pitch_link">
    <inertial>
      <origin xyz="0.00382921 0 -0.1854850" rpy="0 0 0" />
      <!-- <mass value="1.664" /> -->
      <mass value="1.8" />
      <inertia ixx="0.01443710" ixy="-0.00000000" ixz="-0.00089513" iyy="0.01484426" iyz="0.00000003" izz="0.00315739" />
    </inertial>
    <visual>
      <origin xyz="0 0 0" rpy="0 0 0" />
      <geometry>
        <mesh filename="meshes/R_hip_pitch_link.STL" />
      </geometry>
      <material name="">
        <color rgba="1 1 1 1" />
      </material>
    </visual>
    <collision>
      <origin xyz="0.01 0 -0.175" rpy="0 0 0" />
      <geometry>
        <box size="0.11 0.11 0.23" />
      </geometry>
    </collision>
    <!-- <collision>
      <origin xyz="0 0 0" rpy="0 0 0" />
      <geometry>
        <mesh filename="meshes/R_hip_pitch_link.STL" />
      </geometry>
    </collision> -->
  </link>
  <joint name="R_hip_pitch" type="revolute">
    <origin xyz="0.0085 -0.001 -0.11" rpy="0 0 0" />
    <parent link="R_hip_roll_link" />
    <child link="R_hip_pitch_link" />
    <axis xyz="0 -1 0" />
    <limit lower="-0.526" upper="2.4434" effort="72" velocity="111" />
  </joint>
  <link name="R_knee_pitch_link">
    <inertial>
      <origin xyz="0.00140265 0 -0.15875986" rpy="0 0 0" />
      <mass value="1.125" />
      <inertia ixx="0.00985892" ixy="-0.00000000" ixz="0.00035856" iyy="0.00999859" iyz="0.00000003" izz="0.00102379" />
    </inertial>
    <visual>
      <origin xyz="0 0 0" rpy="0 0 0" />
      <geometry>
        <mesh filename="meshes/R_knee_pitch_link.STL" />
      </geometry>
      <material name="">
        <color rgba="1 1 1 1" />
      </material>
    </visual>
    <collision>
      <origin xyz="0 0 0" rpy="0 0 0" />
      <geometry>
        <mesh filename="meshes/R_knee_pitch_link.STL" />
      </geometry>
    </collision>
  </link>
  <joint name="R_knee_pitch" type="revolute">
    <origin xyz="0 0 -0.35" rpy="0 0 0" />
    <parent link="R_hip_pitch_link" />
    <child link="R_knee_pitch_link" />
    <axis xyz="0 -1 0" />
    <limit lower="-2.3561" upper="0" effort="64.8" velocity="247" />
  </joint>
  <link name="R_ankle_pitch_link">
    <inertial>
      <origin xyz="-0.00129654 0.00042952 -0.02564546" rpy="0 0 0" />
      <!-- <mass value="0.176" /> -->
      <mass value="0.2" />
      <inertia ixx="0.00018904" ixy="0.000000108" ixz="0.000000604" iyy="0.00027991" iyz="0.0000000295" izz="0.00013810" />
    </inertial>
    <visual>
      <origin xyz="0 0 0" rpy="0 0 0" />
      <geometry>
        <mesh filename="meshes/R_ankle_pitch_link.STL" />
      </geometry>
      <material name="">
        <color rgba="1 1 1 1" />
      </material>
    </visual>
<!--    <collision>-->
<!--      <origin xyz="0 0 0" rpy="0 0 0" />-->
<!--      <geometry>-->
<!--        <mesh filename="meshes/R_ankle_pitch_link.STL" />-->
<!--      </geometry>-->
<!--    </collision>-->
  </link>
  <joint name="R_ankle_pitch" type="revolute">
    <origin xyz="0 0 -0.35" rpy="0 0 0" />
    <parent link="R_knee_pitch_link" />
    <child link="R_ankle_pitch_link" />
    <axis xyz="0 -1 0" />
    <limit lower="-1.2217" upper="1.2217" effort="64.8" velocity="247" />
  </joint>
  <link name="R_ankle_roll_link">
    <inertial>
      <origin xyz="0.04924005 0.00023785 -0.03446406" rpy="0 0 0" />
      <!-- <mass value="0.624" /> -->
      <mass value="1.0" />
      <inertia ixx="0.00038741" ixy="0.00000505" ixz="0.00004308" iyy="0.00328461" iyz="0.00000022" izz="0.00357836" />
    </inertial>
    <visual>
      <origin xyz="0 0 0" rpy="0 0 0" />
      <geometry>
        <mesh filename="meshes/R_ankle_roll_link.STL" />
      </geometry>
      <material name="">
        <color rgba="1 1 1 1" />
      </material>
    </visual>
    <collision>
       <origin xyz="0 0 0" rpy="0 0 0" />
      <geometry>
        <mesh filename="meshes/R_ankle_roll_link.STL" />
      </geometry>
    </collision>
  </link>
  <joint name="R_ankle_roll" type="revolute">
    <origin xyz="0 0 -0.045" rpy="0 0 0" />
    <parent link="R_ankle_pitch_link" />
    <child link="R_ankle_roll_link" />
    <axis xyz="-1 0 0" />
    <limit lower="-1.047" upper="1.047" effort="20.67" velocity="248" />
  </joint>
  <link name="waist_yaw_link">
    <inertial>
      <origin xyz="0 0 0.00495" rpy="0 0 0" />
      <mass value="0.9" />
      <inertia ixx="0.00064077" ixy="0.00000000" ixz="0.00000000" iyy="0.00064077" iyz="0.00000000" izz="0.00081281" />
    </inertial>
    <visual>
      <origin xyz="0 0 0" rpy="0 0 0" />
      <geometry>
        <mesh filename="meshes/waist_yaw_link.STL" />
      </geometry>
      <material name="">
        <color rgba="1 1 1 1" />
      </material>
    </visual>
    <!-- <collision>
      <origin xyz="0 0 0" rpy="0 0 0" />
      <geometry>
        <mesh filename="meshes/waist_yaw_link.STL" />
      </geometry>
    </collision> -->
  </link>
  <joint name="waist_yaw" type="fixed">
    <origin xyz="0 0 0.08375" rpy="0 0 0" />
    <parent link="pelvis_link" />
    <child link="waist_yaw_link" />
    <axis xyz="0 0 1" />
    <limit lower="-1.047" upper="1.047" effort="83.5" velocity="43" />
  </joint>
  <link name="torso_link">
    <inertial>
      <origin xyz="-0.00574 0 0.18601" rpy="0 0 0" />
      <mass value="10.129" />
      <inertia ixx="0.16142168" ixy="-0.00000008" ixz="-0.00055992" iyy="0.14544225" iyz="-0.00000008" izz="0.08278995" />
    </inertial>
    <visual>
      <origin xyz="0 0 0" rpy="0 0 0" />
      <geometry>
        <mesh filename="meshes/torso_link.STL" />
      </geometry>
      <material name="">
        <color rgba="0.823529411764706 0.823529411764706 0.823529411764706 1" />
      </material>
    </visual>
    <collision>
      <origin xyz="0 0 0" rpy="0 0 0" />
      <geometry>
        <mesh filename="meshes/torso_link.STL" />
      </geometry>
    </collision>
  </link>
  <joint name="torso" type="fixed">
    <origin xyz="0 0 0.03675" rpy="0 0 0" />
    <parent link="waist_yaw_link" />
    <child link="torso_link" />
    <axis xyz="0 0 0" />
  </joint>
  <link name="logo_link">
    <inertial>
      <origin xyz="0.07801 0.00014123 0.21228" rpy="0 0 0" />
      <mass value="0.0051207" />
      <inertia ixx="1.2629E-06" ixy="-5.8501E-11" ixz="4.3873E-07" iyy="1.0993E-06" iyz="5.4154E-10" izz="9.4943E-07" />
    </inertial>
    <visual>
      <origin xyz="0 0 0" rpy="0 0 0" />
      <geometry>
        <mesh filename="meshes/logo_link.STL" />
      </geometry>
      <material name="">
        <color rgba="1 0 0 1" />
      </material>
    </visual>
    <!-- <collision>
      <origin xyz="0 0 0" rpy="0 0 0" />
      <geometry>
        <mesh filename="meshes/logo_link.STL" />
      </geometry>
    </collision> -->
  </link>
  <joint name="logo" type="fixed">
    <origin xyz="0 0 0" rpy="0 0 0" />
    <parent link="torso_link" />
    <child link="logo_link" />
    <axis xyz="0 0 0" />
  </joint>
  <link name="head_link">
    <inertial>
      <origin xyz="0.01547561 0 0.16472894" rpy="0 0 0" />
      <mass value="1.67" />
      <inertia ixx="0.00882503" ixy="0.00000000" ixz="0.00010108" iyy="0.01008134" iyz="0.00000000" izz="0.00524807" />
    </inertial>
    <visual>
      <origin xyz="0 0 0" rpy="0 0 0" />
      <geometry>
        <mesh filename="meshes/head_link.STL" />
      </geometry>
      <material name="">
        <color rgba="1 1 1 1" />
      </material>
    </visual>
    <!-- <collision>
      <origin xyz="0 0 0" rpy="0 0 0" />
      <geometry>
        <mesh filename="meshes/head_link.STL" />
      </geometry>
    </collision> -->
  </link>
  <joint name="head" type="fixed">
    <origin xyz="0 0 0.3645" rpy="0 0 0" />
    <parent link="torso_link" />
    <child link="head_link" />
    <axis xyz="0 0 1" />
    <limit lower="-1.571" upper="1.571" effort="50" velocity="5" />
  </joint>
  <link name="L_shoulder_pitch_link">
    <!-- <inertial>
      <origin xyz="0 0.04701640 0.00351929" rpy="0 0 0" />
      <mass value="0.3" />
      <inertia ixx="0.00158526" ixy="0.00000000" ixz="0.00000000" iyy="0.00116709" iyz="-0.00007424" izz="0.00127903" />
    </inertial> -->
    <inertial>
      <origin xyz="0 0.02913267 0" rpy="0 0 0" />
      <mass value="0.276" />
      <inertia ixx="0.00019627" ixy="0" ixz="0" iyy="0.00021249" iyz="0" izz="0.00033854" />
    </inertial>
    <visual>
      <origin xyz="0 0 0" rpy="0 0 0" />
      <geometry>
        <mesh filename="meshes/L_shoulder_pitch_link.STL" />
      </geometry>
      <material name="">
        <color rgba="0.2 0.2 0.2 1" />
      </material>
    </visual>
    <!-- <collision>
      <origin xyz="0 0 0" rpy="0 0 0" />
      <geometry>
        <mesh filename="meshes/L_shoulder_pitch_link.STL" />
      </geometry>
    </collision> -->
  </link>
  <joint name="L_shoulder_pitch" type="revolute">
    <origin xyz="-0.01 0.14477 0.31534" rpy="0.17453 0 0" />
    <parent link="torso_link" />
    <child link="L_shoulder_pitch_link" />
    <axis xyz="0 -1 0" />
    <limit lower="-1.57" upper="3.14" effort="66" velocity="30" />
  </joint>
  <link name="L_shoulder_roll_link">
    <inertial>
      <origin xyz="0 0.00775110 -0.06232250" rpy="0 0 0" />
      <!-- <mass value="0.8" /> -->
      <mass value="1.126" />
      <inertia ixx="0.00218133" ixy="0.00000000" ixz="-0.00000002" iyy="0.00233772" iyz="0.00000476" izz="0.00132593" />
    </inertial>
    <visual>
      <origin xyz="0 0 0" rpy="0 0 0" />
      <geometry>
        <mesh filename="meshes/L_shoulder_roll_link.STL" />
      </geometry>
      <material name="">
        <color rgba="0.784313725490196 0.784313725490196 0.784313725490196 1" />
      </material>
    </visual>
<!--    <collision>-->
<!--      <origin xyz="0 0 0" rpy="0 0 0" />-->
<!--      <geometry>-->
<!--        <mesh filename="meshes/L_shoulder_roll_link.STL" />-->
<!--      </geometry>-->
<!--    </collision>-->
  </link>
  <joint name="L_shoulder_roll" type="revolute">
    <origin xyz="0 0.051 0" rpy="-0.17453 0 0" />
    <parent link="L_shoulder_pitch_link" />
    <child link="L_shoulder_roll_link" />
    <axis xyz="1 0 0" />
    <limit lower="-0.2" upper="3.3" effort="66" velocity="30" />
  </joint>
  <link name="L_shoulder_yaw_link">
    <inertial>
      <origin xyz="-0.00105208 0 -0.06492352" rpy="0 0 0" />
      <mass value="0.6" />
      <inertia ixx="0.00196507" ixy="0.00000000" ixz="-0.00000051" iyy="0.00183185" iyz="0.00000000" izz="0.00096221" />
    </inertial>
    <visual>
      <origin xyz="0 0 0" rpy="0 0 0" />
      <geometry>
        <mesh filename="meshes/L_shoulder_yaw_link.STL" />
      </geometry>
      <material name="">
        <color rgba="0.784313725490196 0.784313725490196 0.784313725490196 1" />
      </material>
    </visual>
    <collision>
      <origin xyz="0 0 0" rpy="0 0 0" />
      <geometry>
        <mesh filename="meshes/L_shoulder_yaw_link.STL" />
      </geometry>
    </collision>
  </link>
  <joint name="L_shoulder_yaw" type="revolute">
    <origin xyz="0 0.010546 -0.12054" rpy="0.087266 0 0" />
    <parent link="L_shoulder_roll_link" />
    <child link="L_shoulder_yaw_link" />
    <axis xyz="0 0 1" />
    <limit lower="-2.618" upper="2.618" effort="45" velocity="30" />
  </joint>
  <link name="L_elbow_pitch_link">
     <inertial>
      <origin xyz="-0.00690374 0 -0.01218670" rpy="0 0 0" />
      <mass value="0.3" />
      <!-- <mass value="0.8" /> -->
      <inertia ixx="0.00053385" ixy="0.00000000" ixz="0.00006611" iyy="0.00058464" iyz="0.00000000" izz="0.00042287" />
    </inertial>
    <visual>
      <origin xyz="0 0 0" rpy="0 0 0" />
      <geometry>
        <mesh filename="meshes/L_elbow_pitch_link.STL" />
      </geometry>
      <material name="">
        <color rgba="0.2 0.2 0.2 1" />
      </material>
    </visual>
    <collision>
      <origin xyz="-0.01 0.0 -0.1" rpy="0 0 0" />
      <geometry>
        <box size="0.065 0.075 0.12" />
      </geometry>
    </collision>
    <!-- <collision>
      <origin xyz="0 0 0" rpy="0 0 0" />
      <geometry>
        <mesh filename="meshes/L_elbow_pitch_link.STL" />
      </geometry>
    </collision> -->
  </link>
  <joint name="L_elbow_pitch" type="revolute">
    <origin xyz="0.015 -0.0031899 -0.1405" rpy="0 0 0" />
    <parent link="L_shoulder_yaw_link" />
    <child link="L_elbow_pitch_link" />
    <axis xyz="0 -1 0" />
    <limit lower="0" upper="2.443" effort="83.5" velocity="43" />
  </joint>
  <link name="L_elbow_yaw_link">
    <inertial>
      <origin xyz="0 0 -0.07635282" rpy="0 0 0" />
      <mass value="0.692" />
      <inertia ixx="0.00181936" ixy="0.00000000" ixz="0.00000000" iyy="0.00167875" iyz="0.00000000" izz="0.00051526" />
    </inertial>
    <visual>
      <origin xyz="0 0 0" rpy="0 0 0" />
      <geometry>
        <mesh filename="meshes/L_elbow_yaw_link.STL" />
      </geometry>
      <material name="">
        <color rgba="0.784313725490196 0.784313725490196 0.784313725490196 1" />
      </material>
    </visual>
    <!-- <collision>
      <origin xyz="0 0 0" rpy="0 0 0" />
      <geometry>
        <mesh filename="meshes/L_elbow_yaw_link.STL" />
      </geometry>
    </collision> -->
  </link>
  <joint name="L_elbow_yaw" type="fixed">
    <origin xyz="-0.015 0.0031899 -0.06" rpy="0 0 0" />
    <parent link="L_elbow_pitch_link" />
    <child link="L_elbow_yaw_link" />
    <axis xyz="0 0 1" />
    <limit lower="-2.487" upper="2.487" effort="45" velocity="30" />
  </joint>
  <link name="L_wrist_yaw_Link">
    <inertial>
      <origin xyz="0.0054707 0.0020666 -0.097398" rpy="0 0 0" />
      <!-- <mass value="0.692" /> -->
      <mass value="0.38" />
      <inertia ixx="0.00070889" ixy="-3.6471E-05" ixz="4.4198E-05" iyy="0.00081301" iyz="-5.6072E-06" izz="0.00020641" />
    </inertial>
    <visual>
      <origin xyz="0 0 0" rpy="0 0 0" />
      <geometry>
        <mesh filename="meshes/L_wrist_yaw_link.STL" />
      </geometry>
      <material name="">
        <color rgba="1.88 1.904 1.92 1" />
      </material>
    </visual>
    <collision>
      <origin xyz="0 0 0" rpy="0 0 0" />
      <geometry>
        <mesh filename="meshes/L_wrist_yaw_link.STL" />
      </geometry>
    </collision>
  </link>
  <joint name="L_wrist_yaw" type="revolute">
    <origin xyz="-0.01 0 -0.166" rpy="0 0 0.85" />
    <parent link="L_elbow_pitch_link" />
    <child link="L_wrist_yaw_Link" />
    <axis xyz="0 0 1" />
    <limit lower="-2.793" upper="1.57" effort="2.2" velocity="36" />
  </joint>
  <!-- <link name="L_forearm_pitch_link">
    <inertial>
      <origin xyz="0 0 0" rpy="0 0 0" />
      <mass value="0.168" />
      <inertia ixx="0.00008314" ixy="0.00000000" ixz="0.00000000" iyy="0.00007803" iyz="0.00000000" izz="0.00006610" />
    </inertial>
    <visual>
      <origin xyz="0 0 0" rpy="0 0 0" />
      <geometry>
        <mesh filename="meshes/L_forearm_pitch_link.STL" />
      </geometry>
      <material name="">
        <color rgba="0.2 0.2 0.2 1" />
      </material>
    </visual>
    <collision>
      <origin xyz="0 0 0" rpy="0 0 0" />
      <geometry>
        <mesh filename="meshes/L_forearm_pitch_link.STL" />
      </geometry>
    </collision>
  </link>
  <joint name="L_forearm_pitch" type="fixed">
    <origin xyz="0 0 -0.18" rpy="0 0.0041432 0" />
    <parent link="L_elbow_yaw_link" />
    <child link="L_forearm_pitch_link" />
    <axis xyz="0 -1 0" />
    <limit lower="-0.524" upper="0.524" effort="13" velocity="30" />
  </joint>
  <link name="L_forearm_roll_link">
    <inertial>
      <origin xyz="0.00040233 -0.00001070 -0.07509141" rpy="0 0 0" />
      <mass value="0.4" />
      <inertia ixx="0.00088582" ixy="0.00000000" ixz="-0.00001443" iyy="0.00100238" iyz="-0.00000011" izz="0.00032988" />
    </inertial>
    <visual>
      <origin xyz="0 0 0" rpy="0 0 0" />
      <geometry>
        <mesh filename="meshes/L_forearm_roll_link.STL" />
      </geometry>
      <material name="">
        <color rgba="0.784313725490196 0.784313725490196 0.784313725490196 1" />
      </material>
    </visual>
    <collision>
      <origin xyz="0 0 0" rpy="0 0 0" />
      <geometry>
        <mesh filename="meshes/L_forearm_roll_link.STL" />
      </geometry>
    </collision>
  </link>
  <joint name="L_forearm_roll" type="fixed">
    <origin xyz="0 0 0" rpy="0 0 0" />
    <parent link="L_forearm_pitch_link" />
    <child link="L_forearm_roll_link" />
    <axis xyz="1 0 0" />
    <limit lower="-1.57" upper="1.57" effort="3.5" velocity="30" />
  </joint> -->
  <link name="R_shoulder_pitch_link">
    <!-- <inertial>
      <origin xyz="0 -0.04701640 0.00351929" rpy="0 0 0" />
      <mass value="0.3" />
      <inertia ixx="0.00158526" ixy="0.00000000" ixz="0.00000000" iyy="0.00116709" iyz="0.00007424" izz="0.00127903" />
    </inertial> -->
    <inertial>
      <origin xyz="0 0.02913267 0" rpy="0 0 0" />
      <mass value="0.276" />
      <inertia ixx="0.00019627" ixy="0" ixz="0" iyy="0.00021249" iyz="0" izz="0.00033854" />
    </inertial>
    <visual>
      <origin xyz="0 0 0" rpy="0 0 0" />
      <geometry>
        <mesh filename="meshes/R_shoulder_pitch_link.STL" />
      </geometry>
      <material name="">
        <color rgba="0.2 0.2 0.2 1" />
      </material>
    </visual>
    <!-- <collision>
      <origin xyz="0 0 0" rpy="0 0 0" />
      <geometry>
        <mesh filename="meshes/R_shoulder_pitch_link.STL" />
      </geometry>
    </collision> -->
  </link>
  <joint name="R_shoulder_pitch" type="revolute">
    <origin xyz="-0.01 -0.14477 0.31534" rpy="-0.17453 0 0" />
    <parent link="torso_link" />
    <child link="R_shoulder_pitch_link" />
    <axis xyz="0 -1 0" />
    <limit lower="-1.57" upper="3.14" effort="66" velocity="30" />
  </joint>
  <link name="R_shoulder_roll_link">
    <inertial>
      <origin xyz="0 -0.00775110 -0.06232250" rpy="0 0 0" />
      <!-- <mass value="0.8" /> -->
      <mass value="1.126" />
      <inertia ixx="0.00218133" ixy="0.00000000" ixz="0.00000002" iyy="0.00233772" iyz="-0.00000476" izz="0.00132593" />
    </inertial>
    <visual>
      <origin xyz="0 0 0" rpy="0 0 0" />
      <geometry>
        <mesh filename="meshes/R_shoulder_roll_link.STL" />
      </geometry>
      <material name="">
        <color rgba="0.784313725490196 0.784313725490196 0.784313725490196 1" />
      </material>
    </visual>
<!--    <collision>-->
<!--      <origin xyz="0 0 0" rpy="0 0 0" />-->
<!--      <geometry>-->
<!--        <mesh filename="meshes/R_shoulder_roll_link.STL" />-->
<!--      </geometry>-->
<!--    </collision>-->
  </link>
  <joint name="R_shoulder_roll" type="revolute">
    <origin xyz="0 -0.051 0" rpy="0.17453 0 0" />
    <parent link="R_shoulder_pitch_link" />
    <child link="R_shoulder_roll_link" />
    <axis xyz="-1 0 0" />
    <limit lower="-0.2" upper="3.3" effort="66" velocity="30" />
  </joint>
  <link name="R_shoulder_yaw_link">
    <inertial>
      <origin xyz="-0.00105208 0 -0.06492352" rpy="0 0 0" />
      <mass value="0.6" />
      <inertia ixx="0.00196507" ixy="0.00000000" ixz="-0.00000051" iyy="0.00183185" iyz="0.00000000" izz="0.00096221" />
    </inertial>
    <visual>
      <origin xyz="0 0 0" rpy="0 0 0" />
      <geometry>
        <mesh filename="meshes/R_shoulder_yaw_link.STL" />
      </geometry>
      <material name="">
        <color rgba="0.784313725490196 0.784313725490196 0.784313725490196 1" />
      </material>
    </visual>
    <collision>
      <origin xyz="0 0 0" rpy="0 0 0" />
      <geometry>
        <mesh filename="meshes/R_shoulder_yaw_link.STL" />
      </geometry>
    </collision>
  </link>
  <joint name="R_shoulder_yaw" type="revolute">
    <origin xyz="0 -0.010546 -0.12054" rpy="-0.087266 0 0" />
    <parent link="R_shoulder_roll_link" />
    <child link="R_shoulder_yaw_link" />
    <axis xyz="0 0 -1" />
    <limit lower="-2.618" upper="2.618" effort="45" velocity="30" />
  </joint>
  <link name="R_elbow_pitch_link">
    <inertial>
      <origin xyz="-0.00690374 0 -0.01218670" rpy="0 0 0" />
      <mass value="0.3" />
      <!-- <mass value="0.8" /> -->
      <inertia ixx="0.00053385" ixy="0.00000000" ixz="0.00006611" iyy="0.00058464" iyz="0.00000000" izz="0.00042287" />
    </inertial>
    <visual>
      <origin xyz="0 0 0" rpy="0 0 0" />
      <geometry>
        <mesh filename="meshes/R_elbow_pitch_link.STL" />
      </geometry>
      <material name="">
        <color rgba="0.2 0.2 0.2 1" />
      </material>
    </visual>
    <collision>
      <origin xyz="-0.01 0.0 -0.1" rpy="0 0 0" />
      <geometry>
        <box size="0.065 0.075 0.12" />
      </geometry>
    </collision>
    <!-- <collision>
      <origin xyz="0 0 0" rpy="0 0 0" />
      <geometry>
        <mesh filename="meshes/R_elbow_pitch_link.STL" />
      </geometry>
    </collision> -->
  </link>
  <joint name="R_elbow_pitch" type="revolute">
    <origin xyz="0.015 0.0031899 -0.1405" rpy="0 0 0" />
    <parent link="R_shoulder_yaw_link" />
    <child link="R_elbow_pitch_link" />
    <axis xyz="0 -1 0" />
    <limit lower="0" upper="2.443" effort="83.5" velocity="43" />
  </joint>
  <link name="R_elbow_yaw_link">
    <inertial>
      <origin xyz="0 0 -0.07635282" rpy="0 0 0" />
      <mass value="0.692" />
      <inertia ixx="0.00181936" ixy="0.00000000" ixz="0.00000000" iyy="0.00167875" iyz="0.00000000" izz="0.00051526" />
    </inertial>
    <visual>
      <origin xyz="0 0 0" rpy="0 0 0" />
      <geometry>
        <mesh filename="meshes/R_elbow_yaw_link.STL" />
      </geometry>
      <material name="">
        <color rgba="0.78431 0.78431 0.78431 1" />
      </material>
    </visual>
    <!-- <collision>
      <origin xyz="0 0 0" rpy="0 0 0" />
      <geometry>
        <mesh filename="meshes/R_elbow_yaw_link.STL" />
      </geometry>
    </collision> -->
  </link>
  <joint name="R_elbow_yaw" type="fixed">
    <origin xyz="-0.015 -0.0031899 -0.06" rpy="0 0 0" />
    <parent link="R_elbow_pitch_link" />
    <child link="R_elbow_yaw_link" />
    <axis xyz="0 0 -1" />
    <limit lower="-2.487" upper="2.487" effort="45" velocity="30" />
  </joint>
  <!-- <link name="R_forearm_pitch_link">
    <inertial>
      <origin xyz="0 0 0" rpy="0 0 0" />
      <mass value="0.168" />
      <inertia ixx="0.00008314" ixy="0.00000000" ixz="0.00000000" iyy="0.00007803" iyz="0.00000000" izz="0.00006610" />
    </inertial>
    <visual>
      <origin xyz="0 0 0" rpy="0 0 0" />
      <geometry>
        <mesh filename="meshes/R_forearm_pitch_link.STL" />
      </geometry>
      <material name="">
        <color rgba="0.2 0.2 0.2 1" />
      </material>
    </visual>
   <collision>
     <origin xyz="0 0 0" rpy="0 0 0" />
     <geometry>
       <mesh filename="meshes/R_forearm_pitch_link.STL" />
     </geometry>
   </collision>
  </link> -->
  <link name="R_wrist_yaw_Link">
    <inertial>
      <origin xyz="0.005469 -0.0020643 -0.097398" rpy="0 0 0" />
      <!-- <mass value="0.692" /> -->
      <mass value="0.38" />
      <inertia ixx="0.00070888" ixy="3.6471E-05" ixz="4.4192E-05" iyy="0.00081301" iyz="5.6107E-06" izz="0.00020641" />
    </inertial>
    <visual>
      <origin xyz="0 0 0" rpy="0 0 0" />
      <geometry>
        <mesh filename="meshes/R_wrist_yaw_link.STL" />
      </geometry>
      <material name="">
        <color rgba="1.88 1.904 1.92 1" />
      </material>
    </visual>
    <collision>
      <origin xyz="0 0 0" rpy="0 0 0" />
      <geometry>
        <mesh filename="meshes/R_wrist_yaw_link.STL" />
      </geometry>
    </collision>
  </link>
  <joint name="R_wrist_yaw" type="revolute">
    <origin xyz="-0.01 0 -0.166" rpy="0 0 -0.85" />
    <parent link="R_elbow_pitch_link" />
    <child link="R_wrist_yaw_Link" />
    <axis xyz="0 0 -1" />
    <limit lower="-2.793" upper="1.57" effort="2.2" velocity="36" />
  </joint>

  <!-- <joint name="R_forearm_pitch" type="fixed">
    <origin xyz="0 0 -0.18" rpy="0 0.0041439 0" />
    <parent link="R_elbow_yaw_link" />
    <child link="R_forearm_pitch_link" />
    <axis xyz="0 -1 0" />
    <limit lower="-0.524" upper="0.524" effort="13" velocity="30" />
  </joint>
  <link name="R_forearm_roll_Link">
    <inertial>
      <origin xyz="0.00040250 0.00001074 -0.075089141" rpy="0 0 0" />
      <mass value="0.4" />
      <inertia ixx="0.00088582" ixy="0.00000000" ixz="-0.00001443" iyy="0.00100238" iyz="0.00000011" izz="0.00032988" />
    </inertial>
    <visual>
      <origin xyz="0 0 0" rpy="0 0 0" />
      <geometry>
        <mesh filename="meshes/R_forearm_roll_Link.STL" />
      </geometry>
      <material name="">
        <color rgba="0.78431 0.78431 0.78431 1" />
      </material>
    </visual>
    <collision>
      <origin xyz="0 0 0" rpy="0 0 0" />
      <geometry>
        <mesh filename="meshes/R_forearm_roll_Link.STL" />
      </geometry>
    </collision>
  </link>
  <joint name="R_forearm_roll" type="fixed">
    <origin xyz="0 0 0" rpy="0 0 0" />
    <parent link="R_forearm_pitch_link" />
    <child link="R_forearm_roll_Link" />
    <axis xyz="-1 0 0" />
    <limit lower="-1.57" upper="1.57" effort="3.5" velocity="30" />
  </joint> -->
</robot>
