<mujoco model="x2">
  <compiler angle="radian" meshdir="meshes"/>
  <default>
    <joint damping="0.01" armature="0.01" frictionloss="0.01"/>
  </default>
  <asset>
    <mesh name="pelvis_link" file="pelvis_link.STL"/>
    <mesh name="L_hip_yaw_link" file="L_hip_yaw_link.STL"/>
    <mesh name="L_hip_roll_link" file="L_hip_roll_link.STL"/>
    <mesh name="L_hip_pitch_link" file="L_hip_pitch_link.STL"/>
    <mesh name="L_knee_pitch_link" file="L_knee_pitch_link.STL"/>
    <mesh name="L_ankle_pitch_link" file="L_ankle_pitch_link.STL"/>
    <mesh name="L_ankle_roll_link" file="L_ankle_roll_link.STL"/>
    <mesh name="R_hip_yaw_link" file="R_hip_yaw_link.STL"/>
    <mesh name="R_hip_roll_link" file="R_hip_roll_link.STL"/>
    <mesh name="R_hip_pitch_link" file="R_hip_pitch_link.STL"/>
    <mesh name="R_knee_pitch_link" file="R_knee_pitch_link.STL"/>
    <mesh name="R_ankle_pitch_link" file="R_ankle_pitch_link.STL"/>
    <mesh name="R_ankle_roll_link" file="R_ankle_roll_link.STL"/>
    <mesh name="waist_yaw_link" file="waist_yaw_link.STL"/>
    <mesh name="torso_link" file="torso_link.STL"/>
    <mesh name="logo_link" file="logo_link.STL"/>
    <mesh name="head_link" file="head_link.STL"/>
    <mesh name="L_shoulder_pitch_link" file="L_shoulder_pitch_link.STL"/>
    <mesh name="L_shoulder_roll_link" file="L_shoulder_roll_link.STL"/>
    <mesh name="L_shoulder_yaw_link" file="L_shoulder_yaw_link.STL"/>
    <mesh name="L_elbow_pitch_link" file="L_elbow_pitch_link.STL"/>
    <mesh name="L_elbow_yaw_link" file="L_elbow_yaw_link.STL"/>
    <mesh name="L_wrist_yaw_link" file="L_wrist_yaw_link.STL"/>
    <mesh name="R_shoulder_pitch_link" file="R_shoulder_pitch_link.STL"/>
    <mesh name="R_shoulder_roll_link" file="R_shoulder_roll_link.STL"/>
    <mesh name="R_shoulder_yaw_link" file="R_shoulder_yaw_link.STL"/>
    <mesh name="R_elbow_pitch_link" file="R_elbow_pitch_link.STL"/>
    <mesh name="R_elbow_yaw_link" file="R_elbow_yaw_link.STL"/>
    <mesh name="R_wrist_yaw_link" file="R_wrist_yaw_link.STL"/>
  </asset>

  <worldbody>
    <body name="pelvis_link" pos="0 0 0.91">
      <body name="Spine2_link" pos="0 0 0.4">
      </body>
      <site name="imu" pos="0 0 0.1" size="0.01" type="sphere" rgba="0 0 0 0"/>
      <inertial pos="-0.00249113 5.64815e-08 0.33359" quat="0.999874 -3.28915e-08 0.0158828 -2.07062e-06" mass="12.8041" diaginertia="0.410613 0.396251 0.0892179"/>
      <joint name="pelvis_link" type="free" limited="false" actuatorfrclimited="false"/>
      <geom type="mesh" contype="0" conaffinity="0" group="1" density="0" rgba="1 1 1 1" mesh="pelvis_link"/>
      <geom type="mesh" rgba="1 1 1 1" mesh="pelvis_link"/>
      <geom pos="0 0 0.08375" type="mesh" contype="0" conaffinity="0" group="1" density="0" rgba="1 1 1 1" mesh="waist_yaw_link"/>
      <geom pos="0 0 0.1205" type="mesh" contype="0" conaffinity="0" group="1" density="0" rgba="0.823529 0.823529 0.823529 1" mesh="torso_link"/>
      <geom pos="0 0 0.1205" type="mesh" rgba="0.823529 0.823529 0.823529 1" mesh="torso_link"/>
      <geom pos="0 0 0.1205" type="mesh" contype="0" conaffinity="0" group="1" density="0" rgba="1 0 0 1" mesh="logo_link"/>
      <geom pos="0 0 0.485" type="mesh" contype="0" conaffinity="0" group="1" density="0" rgba="1 1 1 1" mesh="head_link"/>
    <body name="L_hip_yaw_link">
      <inertial pos="-0.0005618 0.019831 0.00885104" quat="0.416547 0.491409 -0.566922 0.513426" mass="0.841" diaginertia="0.00175713 0.00175343 0.000573392"/>
      <joint name="L_hip_yaw" pos="0 0 0" axis="0 0 1" range="-0.7854 0.7854" actuatorfrcrange="-83.5 83.5"/>
      <geom type="mesh" contype="0" conaffinity="0" group="1" density="0" rgba="1 1 1 1" mesh="L_hip_yaw_link"/>
      <body name="L_hip_roll_link" pos="-0.0095 0.12 0">
        <inertial pos="-0.0324725 0.00017925 -0.0726484" quat="0.655395 -0.252501 -0.247695 0.667344" mass="2.667" diaginertia="0.0108627 0.0094793 0.00603247"/>
        <joint name="L_hip_roll" pos="0 0 0" axis="1 0 0" range="-0.349 0.524" actuatorfrcrange="-117.8 117.8"/>
        <geom type="mesh" contype="0" conaffinity="0" group="1" density="0" rgba="1 1 1 1" mesh="L_hip_roll_link"/>
        <geom type="mesh" rgba="1 1 1 1" mesh="L_hip_roll_link"/>
        <body name="L_hip_pitch_link" pos="0.0085 -0.001 -0.11">
          <inertial pos="0.00382921 0 -0.185484" quat="0.706562 0.0278169 0.0278188 0.706557" mass="1.664" diaginertia="0.0148443 0.0145077 0.0030868"/>
          <joint name="L_hip_pitch" pos="0 0 0" axis="0 -1 0" range="-0.526 2.4434" actuatorfrcrange="-72 72"/>
          <geom type="mesh" contype="0" conaffinity="0" group="1" density="0" rgba="1 1 1 1" mesh="L_hip_pitch_link"/>
          <geom size="0.055 0.055 0.115" pos="0.01 0 -0.175" type="box" rgba="1 1 1 1"/>
          <body name="L_knee_pitch_link" pos="0 0 -0.35">
            <inertial pos="0.00140265 0 -0.15876" quat="0.706958 -0.0143173 -0.0143148 0.706965" mass="1.125" diaginertia="0.00999859 0.00987345 0.00100926"/>
            <joint name="L_knee_pitch" pos="0 0 0" axis="0 -1 0" range="-2.3561 0" actuatorfrcrange="-64.8 64.8"/>
            <geom type="mesh" contype="0" conaffinity="0" group="1" density="0" rgba="1 1 1 1" mesh="L_knee_pitch_link"/>
            <geom type="mesh" rgba="1 1 1 1" mesh="L_knee_pitch_link"/>
            <body name="L_ankle_pitch_link" pos="0 0 -0.35">
              <inertial pos="-0.00129654 0.00042952 -0.0256455" quat="0.706673 -0.00426419 -0.0041185 0.707515" mass="0.176" diaginertia="0.00027991 0.000189047 0.000138093"/>
              <joint name="L_ankle_pitch" pos="0 0 0" axis="0 -1 0" range="-1.2217 1.2217" actuatorfrcrange="-64.8 64.8"/>
              <geom type="mesh" contype="0" conaffinity="0" group="1" density="0" rgba="1 1 1 1" mesh="L_ankle_pitch_link"/>
              <body name="L_ankle_roll_link" pos="0 0 -0.045">
                <inertial pos="0.0492383 -0.00023816 -0.0344641" quat="-0.000263099 0.702318 0.000963643 0.711863" mass="0.624" diaginertia="0.00357894 0.00328462 0.00038682"/>
                <joint name="L_ankle_roll" pos="0 0 0" axis="1 0 0" range="-1.047 1.047" actuatorfrcrange="-20.67 20.67"/>
                <geom type="mesh" contype="0" conaffinity="0" group="1" density="0" rgba="1 1 1 1" mesh="L_ankle_roll_link"/>
                <geom type="mesh" rgba="1 1 1 1" mesh="L_ankle_roll_link"/>
              </body>
            </body>
          </body>
        </body>
      </body>
    </body>
    <body name="R_hip_yaw_link">
      <inertial pos="-0.00116447 -0.0404494 0" quat="0.707002 0.707002 0.012174 0.012174" mass="0.947" diaginertia="0.00258678 0.00239929 0.000678198"/>
      <joint name="R_hip_yaw" pos="0 0 0" axis="0 0 -1" range="-0.7854 0.7854" actuatorfrcrange="-83.5 83.5"/>
      <geom type="mesh" contype="0" conaffinity="0" group="1" density="0" rgba="1 1 1 1" mesh="R_hip_yaw_link"/>
      <body name="R_hip_roll_link" pos="-0.0095 -0.12 0">
        <inertial pos="-0.0324725 0.00017925 -0.0726484" quat="0.655395 -0.252501 -0.247695 0.667344" mass="2.667" diaginertia="0.0108627 0.0094793 0.00603247"/>
        <joint name="R_hip_roll" pos="0 0 0" axis="-1 0 0" range="-0.349 0.524" actuatorfrcrange="-117.8 117.8"/>
        <geom type="mesh" contype="0" conaffinity="0" group="1" density="0" rgba="1 1 1 1" mesh="R_hip_roll_link"/>
        <geom type="mesh" rgba="1 1 1 1" mesh="R_hip_roll_link"/>
        <body name="R_hip_pitch_link" pos="0.0085 -0.001 -0.11">
          <inertial pos="0.00382921 0 -0.185485" quat="0.706557 0.0278188 0.0278169 0.706562" mass="1.664" diaginertia="0.0148443 0.0145077 0.0030868"/>
          <joint name="R_hip_pitch" pos="0 0 0" axis="0 -1 0" range="-0.526 2.4434" actuatorfrcrange="-72 72"/>
          <geom type="mesh" contype="0" conaffinity="0" group="1" density="0" rgba="1 1 1 1" mesh="R_hip_pitch_link"/>
          <geom size="0.055 0.055 0.115" pos="0.01 0 -0.175" type="box" rgba="1 1 1 1"/>
          <body name="R_knee_pitch_link" pos="0 0 -0.35">
            <inertial pos="0.00140265 0 -0.15876" quat="0.706965 -0.0143148 -0.0143173 0.706958" mass="1.125" diaginertia="0.00999859 0.00987345 0.00100926"/>
            <joint name="R_knee_pitch" pos="0 0 0" axis="0 -1 0" range="-2.3561 0" actuatorfrcrange="-64.8 64.8"/>
            <geom type="mesh" contype="0" conaffinity="0" group="1" density="0" rgba="1 1 1 1" mesh="R_knee_pitch_link"/>
            <geom type="mesh" rgba="1 1 1 1" mesh="R_knee_pitch_link"/>
            <body name="R_ankle_pitch_link" pos="0 0 -0.35">
              <inertial pos="-0.00129654 0.00042952 -0.0256455" quat="0.707515 -0.0041185 -0.00426419 0.706673" mass="0.176" diaginertia="0.00027991 0.000189047 0.000138093"/>
              <joint name="R_ankle_pitch" pos="0 0 0" axis="0 -1 0" range="-1.2217 1.2217" actuatorfrcrange="-64.8 64.8"/>
              <geom type="mesh" contype="0" conaffinity="0" group="1" density="0" rgba="1 1 1 1" mesh="R_ankle_pitch_link"/>
              <body name="R_ankle_roll_link" pos="0 0 -0.045">
                <inertial pos="0.0492401 0.00023785 -0.0344641" quat="0.000963643 0.711863 -0.000263099 0.702318" mass="0.624" diaginertia="0.00357894 0.00328462 0.00038682"/>
                <joint name="R_ankle_roll" pos="0 0 0" axis="-1 0 0" range="-1.047 1.047" actuatorfrcrange="-20.67 20.67"/>
                <geom type="mesh" contype="0" conaffinity="0" group="1" density="0" rgba="1 1 1 1" mesh="R_ankle_roll_link"/>
                <geom type="mesh" rgba="1 1 1 1" mesh="R_ankle_roll_link"/>
              </body>
            </body>
          </body>
        </body>
      </body>
    </body>
    <body name="L_shoulder_pitch_link" pos="-0.01 0.14477 0.43584" quat="0.996195 0.0871543 0 0">
      <inertial pos="0 0.0470164 0.00351929" quat="0.526262 0.850323 0 0" mass="0.763" diaginertia="0.00158526 0.00131603 0.00113009"/>
      <joint name="L_shoulder_pitch" pos="0 0 0" axis="0 -1 0" range="-1.57 3.14" actuatorfrcrange="-66 66"/>
      <geom type="mesh" contype="0" conaffinity="0" group="1" density="0" rgba="0.2 0.2 0.2 1" mesh="L_shoulder_pitch_link"/>
      <body name="L_shoulder_roll_link" pos="0 0.051 0" quat="0.996195 -0.0871543 0 0">
        <inertial pos="0 0.0077511 -0.0623225" quat="0.707105 0.00167152 -0.00165499 0.707105" mass="0.8" diaginertia="0.00233774 0.00218133 0.00132591"/>
        <joint name="L_shoulder_roll" pos="0 0 0" axis="1 0 0" range="-0.2 3.3" actuatorfrcrange="-66 66"/>
        <geom type="mesh" contype="0" conaffinity="0" group="1" density="0" rgba="0.784314 0.784314 0.784314 1" mesh="L_shoulder_roll_link"/>
        <body name="L_shoulder_yaw_link" pos="0 0.010546 -0.12054" quat="0.999048 0.0436192 0 0">
          <inertial pos="-0.00105208 0 -0.0649235" quat="1 0 0.000254273 0" mass="0.5" diaginertia="0.00196507 0.00183185 0.00096221"/>
          <joint name="L_shoulder_yaw" pos="0 0 0" axis="0 0 1" range="-2.618 2.618" actuatorfrcrange="-45 45"/>
          <geom type="mesh" contype="0" conaffinity="0" group="1" density="0" rgba="0.784314 0.784314 0.784314 1" mesh="L_shoulder_yaw_link"/>
          <geom type="mesh" rgba="0.784314 0.784314 0.784314 1" mesh="L_shoulder_yaw_link"/>
          <body name="L_elbow_pitch_link" pos="0.015 -0.0031899 -0.1405">
            <inertial pos="-0.0113222 0.00174086 -0.0799493" quat="0.999561 0.0104759 0.0197797 0.0193908" mass="1.268" diaginertia="0.00721288 0.00713275 0.000949426"/>
            <joint name="L_elbow_pitch" pos="0 0 0" axis="0 -1 0" range="0 2.443" actuatorfrcrange="-83.5 83.5"/>
            <geom type="mesh" contype="0" conaffinity="0" group="1" density="0" rgba="0.2 0.2 0.2 1" mesh="L_elbow_pitch_link"/>
            <geom size="0.0325 0.0375 0.06" pos="-0.01 0 -0.1" type="box" rgba="0.2 0.2 0.2 1"/>
            <geom pos="-0.015 0.0031899 -0.06" type="mesh" contype="0" conaffinity="0" group="1" density="0" rgba="0.784314 0.784314 0.784314 1" mesh="L_elbow_yaw_link"/>
            <body name="L_wrist_yaw_Link" pos="-0.01 0 -0.166" quat="0.911039 0 0 0.412321">
              <inertial pos="0.0054707 0.0020666 -0.097398" quat="0.586264 -0.03629 -0.0238447 0.808955" mass="0.692" diaginertia="0.000825088 0.00070068 0.000202542"/>
              <joint name="L_wrist_yaw" pos="0 0 0" axis="0 0 1" range="-2.793 1.57" actuatorfrcrange="-2.2 2.2"/>
              <geom type="mesh" contype="0" conaffinity="0" group="1" density="0" rgba="1.88 1.904 1.92 1" mesh="L_wrist_yaw_link"/>
              <geom type="mesh" rgba="1.88 1.904 1.92 1" mesh="L_wrist_yaw_link"/>
            </body>
          </body>
        </body>
      </body>
    </body>
    <body name="R_shoulder_pitch_link" pos="-0.01 -0.14477 0.43584" quat="0.996195 -0.0871543 0 0">
      <inertial pos="0 -0.0470164 0.00351929" quat="0.850323 0.526262 0 0" mass="0.763" diaginertia="0.00158526 0.00131603 0.00113009"/>
      <joint name="R_shoulder_pitch" pos="0 0 0" axis="0 -1 0" range="-1.57 3.14" actuatorfrcrange="-66 66"/>
      <geom type="mesh" contype="0" conaffinity="0" group="1" density="0" rgba="0.2 0.2 0.2 1" mesh="R_shoulder_pitch_link"/>
      <body name="R_shoulder_roll_link" pos="0 -0.051 0" quat="0.996195 0.0871543 0 0">
        <inertial pos="0 -0.0077511 -0.0623225" quat="0.707105 -0.00167152 0.00165499 0.707105" mass="0.8" diaginertia="0.00233774 0.00218133 0.00132591"/>
        <joint name="R_shoulder_roll" pos="0 0 0" axis="-1 0 0" range="-0.2 3.3" actuatorfrcrange="-66 66"/>
        <geom type="mesh" contype="0" conaffinity="0" group="1" density="0" rgba="0.784314 0.784314 0.784314 1" mesh="R_shoulder_roll_link"/>
        <body name="R_shoulder_yaw_link" pos="0 -0.010546 -0.12054" quat="0.999048 -0.0436192 0 0">
          <inertial pos="-0.00105208 0 -0.0649235" quat="1 0 0.000254273 0" mass="0.5" diaginertia="0.00196507 0.00183185 0.00096221"/>
          <joint name="R_shoulder_yaw" pos="0 0 0" axis="0 0 -1" range="-2.618 2.618" actuatorfrcrange="-45 45"/>
          <geom type="mesh" contype="0" conaffinity="0" group="1" density="0" rgba="0.784314 0.784314 0.784314 1" mesh="R_shoulder_yaw_link"/>
          <geom type="mesh" rgba="0.784314 0.784314 0.784314 1" mesh="R_shoulder_yaw_link"/>
          <body name="R_elbow_pitch_link" pos="0.015 0.0031899 -0.1405">
            <inertial pos="-0.0113222 -0.00174086 -0.0799493" quat="0.999561 -0.0104759 0.0197797 -0.0193908" mass="1.268" diaginertia="0.00721288 0.00713275 0.000949426"/>
            <joint name="R_elbow_pitch" pos="0 0 0" axis="0 -1 0" range="0 2.443" actuatorfrcrange="-83.5 83.5"/>
            <geom type="mesh" contype="0" conaffinity="0" group="1" density="0" rgba="0.2 0.2 0.2 1" mesh="R_elbow_pitch_link"/>
            <geom size="0.0325 0.0375 0.06" pos="-0.01 0 -0.1" type="box" rgba="0.2 0.2 0.2 1"/>
            <geom pos="-0.015 -0.0031899 -0.06" type="mesh" contype="0" conaffinity="0" group="1" density="0" rgba="0.78431 0.78431 0.78431 1" mesh="R_elbow_yaw_link"/>
            <body name="R_wrist_yaw_Link" pos="-0.01 0 -0.166" quat="0.911039 0 0 -0.412321">
              <inertial pos="0.005469 -0.0020643 -0.097398" quat="0.808948 -0.0238396 -0.0362874 0.586274" mass="0.692" diaginertia="0.000825087 0.00070067 0.000202543"/>
              <joint name="R_wrist_yaw" pos="0 0 0" axis="0 0 -1" range="-2.793 1.57" actuatorfrcrange="-2.2 2.2"/>
              <geom type="mesh" contype="0" conaffinity="0" group="1" density="0" rgba="1.88 1.904 1.92 1" mesh="R_wrist_yaw_link"/>
              <geom type="mesh" rgba="1.88 1.904 1.92 1" mesh="R_wrist_yaw_link"/>
            </body>
          </body>
        </body>
      </body>
    </body>
</body>
  </worldbody>
  <actuator>
    <motor name="L_hip_yaw" joint="L_hip_yaw"  ctrlrange="-50.0 50.0" ctrllimited="true" />
    <motor name="L_hip_roll" joint="L_hip_roll"  ctrlrange="-110.0 110.0" ctrllimited="true" />
    <motor name="L_hip_pitch" joint="L_hip_pitch" ctrlrange="-72.0 72.0" ctrllimited="true" />
    <motor name="L_knee_pitch" joint="L_knee_pitch" ctrlrange="-150.0 150.0" ctrllimited="true" />
    <motor name="L_ankle_pitch" joint="L_ankle_pitch" ctrlrange="-45.0 45.0" ctrllimited="true" />
    <motor name="L_ankle_roll" joint="L_ankle_roll" ctrlrange="-20.0 20.0" ctrllimited="true" />

    <motor name="R_hip_yaw" joint="R_hip_yaw"    ctrlrange="-50.0 50.0" ctrllimited="true" />
    <motor name="R_hip_roll" joint="R_hip_roll"   ctrlrange="-110.0 110.0" ctrllimited="true" />
    <motor name="R_hip_pitch" joint="R_hip_pitch"   ctrlrange="-72.0 72.0" ctrllimited="true" />
    <motor name="R_knee_pitch" joint="R_knee_pitch"  ctrlrange="-150.0 150.0" ctrllimited="true" />
    <motor name="R_ankle_pitch" joint="R_ankle_pitch" ctrlrange="-45.0 45.0" ctrllimited="true" />
    <motor name="R_ankle_roll" joint="R_ankle_roll" ctrlrange="-20.0 20.0" ctrllimited="true" />

    <motor name="L_shoulder_pitch" joint="L_shoulder_pitch" ctrlrange="-20.0 20.0" ctrllimited="true" />
    <motor name="L_shoulder_roll"  joint="L_shoulder_roll"  ctrlrange="-20.0 20.0" ctrllimited="true" />
    <motor name="L_shoulder_yaw"   joint="L_shoulder_yaw"   ctrlrange="-20.0 20.0" ctrllimited="true" />
    <motor name="L_elbow_pitch"    joint="L_elbow_pitch"    ctrlrange="-20.0 20.0" ctrllimited="true" />
    <motor name="L_wrist_yaw"    joint="L_wrist_yaw"    ctrlrange="-10.0 10.0" ctrllimited="true" />

    <motor name="R_shoulder_pitch" joint="R_shoulder_pitch" ctrlrange="-20.0 20.0" ctrllimited="true" />
    <motor name="R_shoulder_roll"  joint="R_shoulder_roll"  ctrlrange="-20.0 20.0" ctrllimited="true" />
    <motor name="R_shoulder_yaw"   joint="R_shoulder_yaw"   ctrlrange="-20.0 20.0" ctrllimited="true" />
    <motor name="R_elbow_pitch"    joint="R_elbow_pitch"    ctrlrange="-20.0 20.0" ctrllimited="true" />
    <motor name="R_wrist_yaw"    joint="R_wrist_yaw"    ctrlrange="-10.0 10.0" ctrllimited="true" />
  </actuator>
  <sensor>
<!-- 身体的的姿态 -->
    <gyro          name="gyro"    site='imu' />
    <accelerometer name="acc"     site='imu'/>
    <framequat     name='bq'      objtype='site' objname='imu'/>
    <velocimeter name='blv' site='imu' noise='0.001' cutoff='30'/>
  </sensor>
</mujoco>
